Workbook

Sheet Summary
A1: Project Name/ Number | B1: Bhumae Wellness
A2: Test Case Authorizing Date | B2: 46304 | C2: Application | E2: Bhumae Wellness e-commerce website (bhumaewellness.com) | F2: Authorizing Effort | G2: 8 hrs
F3: Execution Effort | G3: 22.5 hrs
A4: Plan Author | B4: Kuldeep Tiru
A5: Test Execution Date | B5: 10 to 13 Oct | C5: Version | E5: Version 1 | F5: Environment | G5: Production (live site)
F6: Actual Time | G6: 30 hrs
A7: Test Executed By | B7: Kuldeep Tiru
A8: Test Status | B8: Executed, pending review
A9: Scope | B9: Entire website: storefront (home, collection, product, bag, checkout, PIN code, discounts, COD), emails, order tracking, account, policy and contact pages, admin (orders, invoice, products, discounts, content), plus responsive, compatibility, accessibility, performance and basic security checks. Includes the client plan (35 checks S1-S14, T1-T6, A1-A11, D1-D4) and added cases.
A10: Test Purpose or Objective | B10: Confirm the site is ready for launch on Oct 12, 2026. Complete execution by Oct 11, 2026 and report defects with device, browser, URL, steps, actual vs expected and evidence.
A11: Set Up Requirements or Considerations | B11: Android phone (Chrome), iPhone (Safari), desktop (Chrome or Edge, Firefox), Mac Safari if available. Own name, mobile and email on test orders. Admin password shared separately.
A12: Notes or Special Instructions | B12: Every order is real in the system. Cancel each test order in admin and note its BHU reference. Do NOT click Ship via courier partner. Restore any price, stock or photo that is edited. Create discount codes (ADM_010) before DISC_001.
A13: Database Changes | B13: Test data created during execution was cleaned up after testing.
A14: Hardware or Network | B14: Android, iPhone, desktop and Mac browsers; Wi-Fi and mobile data; Chrome DevTools and Lighthouse.
A15: Items not included in test | B15: Online payment (payment gateway), customer sign-in by SMS, Ship via courier partner, shipping labels, live courier tracking (client excluded). Load testing, penetration testing, database access.
A16: Assumptions | B16: Business rules agreed with the client at the start: free-shipping threshold, quantity cap, COD limit and GST-inclusive pricing.
A18: Work Sheets in Test plan | B18: All the projects should have Functional testing, Regression Testing work sheets. New work sheets can be added in case of the testing multiple modules/applications/roles/permissions
A19: Defect List | B19: All the defects should be tracked in the test plan.

Sheet Execution Plan
A1: Phase | B1: When | C1: Test Case Ids | D1: Dependency and notes | E1: Est. hours
A2: 0. Setup | B2: Oct 10 | C2: ADM_001, ADM_010, PIN_012 | D2: Get admin password and devices ready. Record every product price, MRP, stock and photo before editing anything (baseline stock 24, 24, 25, 25, 25). Create discount codes first (needed by DISC_001, DISC_002, DISC_003). Prepare a folder for screenshots. | E2: 0.5
A3: 1. Storefront on desktop | B3: Oct 10 | C3: HOME_001, HOME_002, COLL_001, COLL_002, PDP_001, PDP_002, BAG_001, BAG_002, BAG_003, BAG_004, BAG_007, CHK_001, CHK_002, CHK_003, PIN_001, PIN_002, PIN_003, PAY_001, PAY_002, DISC_001, DISC_002, DISC_003, DISC_004, COLL_003, COLL_004, PDP_006, PDP_007, PDP_008, PDP_009, BAG_010, BAG_011, PAY_003, NAV_006, NAV_007, NAV_008 | D3: No orders placed yet. Use PIN data from the client table. | E3: 5.5
A4: 2. Order, emails, tracking, invoice | B4: Oct 10 | C4: ORD_001 (also place one order to 110001), CHK_010, ORD_002, ORD_003, CHK_004, EML_001, EML_002, EML_003, TRK_001, TRK_002, TRK_003, TRK_004, ADM_002, ADM_003, ADM_017, ADM_004, then ADM_005 | D4: Needs the S11 order. Cancel (ADM_005) only after invoice, tracking and email checks are finished. Write BHU references in Notes. | E4: 3.5
A5: 3. Admin and stock | B5: Oct 10 late or Oct 11 early | C5: ADM_006, STK_001, ORD_004, BAG_008, ADM_007, ADM_008, ADM_009, ADM_013, ADM_014, ADM_015, ADM_016, ADM_018, ADM_012, SEC_001, ADM_019, ADM_020, ADM_021, ADM_022, ADM_023, ADM_025, ADM_026, SEC_002, ADM_011, ACC_001, POL_001, POL_002 | D5: Restore price, stock and photos after each check. Delete test products at the end. Never click Ship via courier partner. Change payment settings only in a quiet period and restore. | E5: 5
A6: 4. Devices | B6: Oct 11 AM | C6: DEV_001, DEV_002, DEV_003, DEV_004, CHK_007, NAV_002, PDP_004, UI_001 | D6: Each device run places a real order. Cancel it and note the BHU reference. | E6: 3
A7: 5. Remaining and non-functional | B7: Oct 11 (stretch) | C7: NAV_001, NAV_003, NAV_004, NAV_005, HOME_003, PDP_003, PDP_005, BAG_005, BAG_006, BAG_009, CHK_005, CHK_006, CHK_008, CHK_009, ORD_005, UI_002, UI_003, UI_004, UI_005, UI_006, UI_007, UI_008, UI_009, EXP_001 | D7: Stretch phase. If time runs short, run High priority cases only and report the rest as Not Executed. Exploratory session is time-boxed to 60 minutes per device. | E7: 3.5
A8: 6. Retest and wrap-up | B8: Oct 11 PM | C8: Regression sheet (High priority cases), all Failed and Blocked cases | D8: Retest fixes. Cancel all test orders, restore data, update Defects sheet and send the summary report before the deadline. | E8: 1.5
A9: Total | E9: =SUM(E2:E8) -> 22.5
A10: Prefix TC_BW_ is omitted in Case Ids for brevity (for example ADM_001 means TC_BW_ADM_001).

Sheet Coverage
A1: Test Type | B1: Total | C1: Pass | D1: Fail | E1: Blocked | F1: Not Executed | G1: % Executed
A2: Accessibility | B2: =COUNTIF('Functional Testing'!$M$2:$M$349,A2) -> 1 | C2: =COUNTIFS('Functional Testing'!$M$2:$M$349,$A2,'Functional Testing'!$L$2:$L$349,"Pass") -> 1 | D2: =COUNTIFS('Functional Testing'!$M$2:$M$349,$A2,'Functional Testing'!$L$2:$L$349,"Fail") -> 0 | E2: =COUNTIFS('Functional Testing'!$M$2:$M$349,$A2,'Functional Testing'!$L$2:$L$349,"Blocked") -> 0 | F2: =COUNTIFS('Functional Testing'!$M$2:$M$349,$A2,'Functional Testing'!$L$2:$L$349,"Not Executed") -> 0 | G2: =IF(B2=0,0,(C2+D2+E2)/B2) -> 1
A3: Admin | B3: =COUNTIF('Functional Testing'!$M$2:$M$349,A3) -> 16 | C3: =COUNTIFS('Functional Testing'!$M$2:$M$349,$A3,'Functional Testing'!$L$2:$L$349,"Pass") -> 14 | D3: =COUNTIFS('Functional Testing'!$M$2:$M$349,$A3,'Functional Testing'!$L$2:$L$349,"Fail") -> 0 | E3: =COUNTIFS('Functional Testing'!$M$2:$M$349,$A3,'Functional Testing'!$L$2:$L$349,"Blocked") -> 2 | F3: =COUNTIFS('Functional Testing'!$M$2:$M$349,$A3,'Functional Testing'!$L$2:$L$349,"Not Executed") -> 0 | G3: =IF(B3=0,0,(C3+D3+E3)/B3) -> 1
A4: Boundary | B4: =COUNTIF('Functional Testing'!$M$2:$M$349,A4) -> 6 | C4: =COUNTIFS('Functional Testing'!$M$2:$M$349,$A4,'Functional Testing'!$L$2:$L$349,"Pass") -> 5 | D4: =COUNTIFS('Functional Testing'!$M$2:$M$349,$A4,'Functional Testing'!$L$2:$L$349,"Fail") -> 0 | E4: =COUNTIFS('Functional Testing'!$M$2:$M$349,$A4,'Functional Testing'!$L$2:$L$349,"Blocked") -> 1 | F4: =COUNTIFS('Functional Testing'!$M$2:$M$349,$A4,'Functional Testing'!$L$2:$L$349,"Not Executed") -> 0 | G4: =IF(B4=0,0,(C4+D4+E4)/B4) -> 1
A5: Compatibility | B5: =COUNTIF('Functional Testing'!$M$2:$M$349,A5) -> 5 | C5: =COUNTIFS('Functional Testing'!$M$2:$M$349,$A5,'Functional Testing'!$L$2:$L$349,"Pass") -> 3 | D5: =COUNTIFS('Functional Testing'!$M$2:$M$349,$A5,'Functional Testing'!$L$2:$L$349,"Fail") -> 0 | E5: =COUNTIFS('Functional Testing'!$M$2:$M$349,$A5,'Functional Testing'!$L$2:$L$349,"Blocked") -> 1 | F5: =COUNTIFS('Functional Testing'!$M$2:$M$349,$A5,'Functional Testing'!$L$2:$L$349,"Not Executed") -> 0 | G5: =IF(B5=0,0,(C5+D5+E5)/B5) -> 0.8
A6: Content | B6: =COUNTIF('Functional Testing'!$M$2:$M$349,A6) -> 6 | C6: =COUNTIFS('Functional Testing'!$M$2:$M$349,$A6,'Functional Testing'!$L$2:$L$349,"Pass") -> 6 | D6: =COUNTIFS('Functional Testing'!$M$2:$M$349,$A6,'Functional Testing'!$L$2:$L$349,"Fail") -> 0 | E6: =COUNTIFS('Functional Testing'!$M$2:$M$349,$A6,'Functional Testing'!$L$2:$L$349,"Blocked") -> 0 | F6: =COUNTIFS('Functional Testing'!$M$2:$M$349,$A6,'Functional Testing'!$L$2:$L$349,"Not Executed") -> 0 | G6: =IF(B6=0,0,(C6+D6+E6)/B6) -> 1
A7: Data Integrity | B7: =COUNTIF('Functional Testing'!$M$2:$M$349,A7) -> 13 | C7: =COUNTIFS('Functional Testing'!$M$2:$M$349,$A7,'Functional Testing'!$L$2:$L$349,"Pass") -> 12 | D7: =COUNTIFS('Functional Testing'!$M$2:$M$349,$A7,'Functional Testing'!$L$2:$L$349,"Fail") -> 1 | E7: =COUNTIFS('Functional Testing'!$M$2:$M$349,$A7,'Functional Testing'!$L$2:$L$349,"Blocked") -> 0 | F7: =COUNTIFS('Functional Testing'!$M$2:$M$349,$A7,'Functional Testing'!$L$2:$L$349,"Not Executed") -> 0 | G7: =IF(B7=0,0,(C7+D7+E7)/B7) -> 1
A8: Email | B8: =COUNTIF('Functional Testing'!$M$2:$M$349,A8) -> 4 | C8: =COUNTIFS('Functional Testing'!$M$2:$M$349,$A8,'Functional Testing'!$L$2:$L$349,"Pass") -> 4 | D8: =COUNTIFS('Functional Testing'!$M$2:$M$349,$A8,'Functional Testing'!$L$2:$L$349,"Fail") -> 0 | E8: =COUNTIFS('Functional Testing'!$M$2:$M$349,$A8,'Functional Testing'!$L$2:$L$349,"Blocked") -> 0 | F8: =COUNTIFS('Functional Testing'!$M$2:$M$349,$A8,'Functional Testing'!$L$2:$L$349,"Not Executed") -> 0 | G8: =IF(B8=0,0,(C8+D8+E8)/B8) -> 1
A9: End-to-End | B9: =COUNTIF('Functional Testing'!$M$2:$M$349,A9) -> 1 | C9: =COUNTIFS('Functional Testing'!$M$2:$M$349,$A9,'Functional Testing'!$L$2:$L$349,"Pass") -> 1 | D9: =COUNTIFS('Functional Testing'!$M$2:$M$349,$A9,'Functional Testing'!$L$2:$L$349,"Fail") -> 0 | E9: =COUNTIFS('Functional Testing'!$M$2:$M$349,$A9,'Functional Testing'!$L$2:$L$349,"Blocked") -> 0 | F9: =COUNTIFS('Functional Testing'!$M$2:$M$349,$A9,'Functional Testing'!$L$2:$L$349,"Not Executed") -> 0 | G9: =IF(B9=0,0,(C9+D9+E9)/B9) -> 1
A10: Error Handling | B10: =COUNTIF('Functional Testing'!$M$2:$M$349,A10) -> 4 | C10: =COUNTIFS('Functional Testing'!$M$2:$M$349,$A10,'Functional Testing'!$L$2:$L$349,"Pass") -> 3 | D10: =COUNTIFS('Functional Testing'!$M$2:$M$349,$A10,'Functional Testing'!$L$2:$L$349,"Fail") -> 1 | E10: =COUNTIFS('Functional Testing'!$M$2:$M$349,$A10,'Functional Testing'!$L$2:$L$349,"Blocked") -> 0 | F10: =COUNTIFS('Functional Testing'!$M$2:$M$349,$A10,'Functional Testing'!$L$2:$L$349,"Not Executed") -> 0 | G10: =IF(B10=0,0,(C10+D10+E10)/B10) -> 1
A11: Exploratory | B11: =COUNTIF('Functional Testing'!$M$2:$M$349,A11) -> 1 | C11: =COUNTIFS('Functional Testing'!$M$2:$M$349,$A11,'Functional Testing'!$L$2:$L$349,"Pass") -> 1 | D11: =COUNTIFS('Functional Testing'!$M$2:$M$349,$A11,'Functional Testing'!$L$2:$L$349,"Fail") -> 0 | E11: =COUNTIFS('Functional Testing'!$M$2:$M$349,$A11,'Functional Testing'!$L$2:$L$349,"Blocked") -> 0 | F11: =COUNTIFS('Functional Testing'!$M$2:$M$349,$A11,'Functional Testing'!$L$2:$L$349,"Not Executed") -> 0 | G11: =IF(B11=0,0,(C11+D11+E11)/B11) -> 1
A12: Functional | B12: =COUNTIF('Functional Testing'!$M$2:$M$349,A12) -> 22 | C12: =COUNTIFS('Functional Testing'!$M$2:$M$349,$A12,'Functional Testing'!$L$2:$L$349,"Pass") -> 19 | D12: =COUNTIFS('Functional Testing'!$M$2:$M$349,$A12,'Functional Testing'!$L$2:$L$349,"Fail") -> 1 | E12: =COUNTIFS('Functional Testing'!$M$2:$M$349,$A12,'Functional Testing'!$L$2:$L$349,"Blocked") -> 2 | F12: =COUNTIFS('Functional Testing'!$M$2:$M$349,$A12,'Functional Testing'!$L$2:$L$349,"Not Executed") -> 0 | G12: =IF(B12=0,0,(C12+D12+E12)/B12) -> 1
A13: Integration | B13: =COUNTIF('Functional Testing'!$M$2:$M$349,A13) -> 2 | C13: =COUNTIFS('Functional Testing'!$M$2:$M$349,$A13,'Functional Testing'!$L$2:$L$349,"Pass") -> 1 | D13: =COUNTIFS('Functional Testing'!$M$2:$M$349,$A13,'Functional Testing'!$L$2:$L$349,"Fail") -> 1 | E13: =COUNTIFS('Functional Testing'!$M$2:$M$349,$A13,'Functional Testing'!$L$2:$L$349,"Blocked") -> 0 | F13: =COUNTIFS('Functional Testing'!$M$2:$M$349,$A13,'Functional Testing'!$L$2:$L$349,"Not Executed") -> 0 | G13: =IF(B13=0,0,(C13+D13+E13)/B13) -> 1
... A23: Validation | B23: =COUNTIF('Functional Testing'!$M$2:$M$349,A23) -> 5 | C23: =COUNTIFS('Functional Testing'!$M$2:$M$349,$A23,'Functional Testing'!$L$2:$L$349,"Pass") -> 3 | D23: =COUNTIFS('Functional Testing'!$M$2:$M$349,$A23,'Functional Testing'!$L$2:$L$349,"Fail") -> 2 | E23: =COUNTIFS('Functional Testing'!$M$2:$M$349,$A23,'Functional Testing'!$L$2:$L$349,"Blocked") -> 0 | F23: =COUNTIFS('Functional Testing'!$M$2:$M$349,$A23,'Functional Testing'!$L$2:$L$349,"Not Executed") -> 0 | G23: =IF(B23=0,0,(C23+D23+E23)/B23) -> 1
A24: Total | B24: =SUM(B2:B23) -> 113 | C24: =SUM(C2:C23) -> 94 | D24: =SUM(D2:D23) -> 9 | E24: =SUM(E2:E23) -> 8 | F24: =SUM(F2:F23) -> 0 | G24: =IF(B24=0,0,(C24+D24+E24)/B24) -> 0.98230088
A26: Priority summary
A27: Priority | B27: Total | C27: Pass | D27: Fail | E27: Blocked | F27: Not Executed | G27: % Executed
A28: High | B28: =COUNTIF('Functional Testing'!$K$2:$K$349,A28) -> 61 | C28: =COUNTIFS('Functional Testing'!$K$2:$K$349,$A28,'Functional Testing'!$L$2:$L$349,"Pass") -> 50 | D28: =COUNTIFS('Functional Testing'!$K$2:$K$349,$A28,'Functional Testing'!$L$2:$L$349,"Fail") -> 8 | E28: =COUNTIFS('Functional Testing'!$K$2:$K$349,$A28,'Functional Testing'!$L$2:$L$349,"Blocked") -> 3 | F28: =COUNTIFS('Functional Testing'!$K$2:$K$349,$A28,'Functional Testing'!$L$2:$L$349,"Not Executed") -> 0 | G28: =IF(B28=0,0,(C28+D28+E28)/B28) -> 1
A29: Medium | B29: =COUNTIF('Functional Testing'!$K$2:$K$349,A29) -> 44 | C29: =COUNTIFS('Functional Testing'!$K$2:$K$349,$A29,'Functional Testing'!$L$2:$L$349,"Pass") -> 38 | D29: =COUNTIFS('Functional Testing'!$K$2:$K$349,$A29,'Functional Testing'!$L$2:$L$349,"Fail") -> 1 | E29: =COUNTIFS('Functional Testing'!$K$2:$K$349,$A29,'Functional Testing'!$L$2:$L$349,"Blocked") -> 4 | F29: =COUNTIFS('Functional Testing'!$K$2:$K$349,$A29,'Functional Testing'!$L$2:$L$349,"Not Executed") -> 0 | G29: =IF(B29=0,0,(C29+D29+E29)/B29) -> 0.97727273
A30: Low | B30: =COUNTIF('Functional Testing'!$K$2:$K$349,A30) -> 8 | C30: =COUNTIFS('Functional Testing'!$K$2:$K$349,$A30,'Functional Testing'!$L$2:$L$349,"Pass") -> 6 | D30: =COUNTIFS('Functional Testing'!$K$2:$K$349,$A30,'Functional Testing'!$L$2:$L$349,"Fail") -> 0 | E30: =COUNTIFS('Functional Testing'!$K$2:$K$349,$A30,'Functional Testing'!$L$2:$L$349,"Blocked") -> 1 | F30: =COUNTIFS('Functional Testing'!$K$2:$K$349,$A30,'Functional Testing'!$L$2:$L$349,"Not Executed") -> 0 | G30: =IF(B30=0,0,(C30+D30+E30)/B30) -> 0.875
A33: Not covered in this round
A34: Area | B34: Reason | C34: Suggested owner
A35: Load and stress testing | B35: Needs tooling (k6, JMeter) and a staging target, not manual | C35: Developer
A36: Penetration or vulnerability scan | B36: Only basic manual security checks are done (SEC cases) | C36: Developer or security vendor
A37: Online payment (UPI, cards) | B37: Switched off until payment gateway approves the account (client) | C37: Retest when live
A38: Customer sign-in by SMS | B38: Waiting on SMS registration (client) | C38: Retest when live
A39: Ship via courier partner, labels, live courier tracking | B39: Books a real courier and charges the wallet (client) | C39: Developer
A40: Database and API level checks | B40: No database access; network tab observation only | C40: Developer
A41: Older OS and browser versions, device farm | B41: Only the available devices are tested | C41: Optional
A42: Email clients beyond Gmail and one more | B42: Partial coverage in EML_003 | C42: Optional
A43: Legal and tax compliance review | B43: Invoice maths is checked; legal wording and GSTIN rules are for the client | C43: Client or CA

Sheet Functional Testing
A1: Test Case Id | B1: Requirement # | C1: Test Scenario | D1: Test Cases | E1: Pre-condition | F1: Test Steps | G1: Step Description | H1: Test data | I1: Expected Results | J1: Actual Results | K1: Priority | L1: Status | M1: Test Type | N1: Run On
A2: TC_BW_HOME_001 | B2: S1 | C2: Home page | D2: Verify home page, product carousel and links | E2: Fresh browser session | F2: Step 01 | G2: Open the home page | H2: https://bhumaewellness.com | I2: Page loads with no errors; carousel moves; links open the right pages | K2: High | L2: Pass | M2: Functional | N2: Both
F3: Step 02 | G3: Move the product carousel
F4: Step 03 | G4: Click a few links
A5: TC_BW_COLL_001 | B5: S2 | C5: Collection page | D5: Verify category tabs and search | E5: Collection page reachable | F5: Step 01 | G5: Open /collection | H5: Search: rose | I5: Each tab shows only its products and the tab counts are correct; search finds Rose Petal Powder; sorting reorders the list | K5: High | L5: Blocked | M5: Functional | N5: Both
F6: Step 02 | G6: Click each category tab and compare the count in brackets with the products shown
F7: Step 03 | G7: Search 'rose'
F8: Step 04 | G8: Use the Sort products dropdown
A9: TC_BW_PDP_001 | B9: S3 | C9: Product page | D9: Verify product page photos, price, reviews and WhatsApp | E9: Any product | F9: Step 01 | G9: Open /products/beetroot | H9: Beetroot Powder, price ₹399 | I9: Photos switch; price and MRP shown; Reviews says 'No reviews yet'; WhatsApp opens; every tab shows its own content | K9: High | L9: Pass | M9: Functional | N9: Both
F10: Step 02 | G10: Click each gallery photo (4 thumbnails)
F11: Step 03 | G11: Open each tab: The Ritual & Directions, Ingredients & Provenance, Pouch Specifications, Reviews (0)
F12: Step 04 | G12: Click Consult on WhatsApp with Practitioner
A13: TC_BW_BAG_001 | B13: S4 | C13: Bag | D13: Verify bag add, quantity change, remove and free-delivery note | E13: Empty bag | F13: Step 01 | G13: Add Beetroot (₹399) and Orange Peel (₹349) to the bag | H13: Beetroot 399, Orange Peel 349 | I13: Bag opens as 'The Bag (n)'; subtotal, shipping and total update correctly; the 'Add ₹X more for FREE shipping' note and progress bar update (₹399 alone shows 'Add ₹200 more') | K13: High | L13: Pass | M13: Functional | N13: Both
F14: Step 02 | G14: Open the bag and change quantities
F15: Step 03 | G15: Remove one product
F16: Step 04 | G16: Compare subtotal, shipping and total with a manual calculation
A17: TC_BW_BAG_002 | B17: S5 | C17: Bag | D17: Verify quantity limit of 10 | E17: 1 product in bag | F17: Step 01 | G17: Increase one product quantity to 10 | H17: 10, 11 | I17: Quantity stops at 10 | K17: High | L17: Pass | M17: Boundary | N17: Both
F18: Step 02 | G18: Try to set 11 (button and typed)
A19: TC_BW_CHK_001 | B19: S6 | C19: Checkout form | D19: Verify empty and invalid checkout fields | E19: Item in bag, on checkout | F19: Step 01 | G19: Click Place Order with empty fields | H19: Phone 12345, email abc@ | I19: A clear error under each required field (email, mobile, address, city, state, PIN; confirm whether Full name is required, its label shows no asterisk); no order placed | K19: High | L19: Pass | M19: Validation | N19: Both
F20: Step 02 | G20: Enter phone 12345 and a wrong email
F21: Step 03 | G21: Click Place Order
A22: TC_BW_PIN_001 | B22: S7 | C22: PIN code | D22: Verify deliverable PIN 202002 | E22: On checkout | F22: Step 01 | G22: Enter PIN 202002 with city empty | H22: 202002 | I22: 'Delivery available to Aligarh'; city fills in by itself if empty | K22: High | L22: Pass | M22: Functional | N22: Both
F23: Step 02 | G23: Observe message and city field
A24: TC_BW_PIN_002 | B24: S8 | C24: PIN code | D24: Verify non-served PIN 744101 blocks order | E24: Valid details filled | F24: Step 01 | G24: Enter PIN 744101 | H24: 744101 (Port Blair) | I24: Message that the courier does not deliver there yet; order not placed | K24: High | L24: Pass | M24: Negative | N24: Both
F25: Step 02 | G25: Read the message
F26: Step 03 | G26: Try to place the order
A27: TC_BW_PIN_003 | B27: S9 | C27: PIN code | D27: Verify non-real PIN 999999 blocks order | E27: Valid details filled | F27: Step 01 | G27: Enter PIN 999999 | H27: 999999 | I27: '999999 is not a valid PIN code'; order not placed | K27: High | L27: Pass | M27: Negative | N27: Both
F28: Step 02 | G28: Read the message
F29: Step 03 | G29: Try to place the order
A30: TC_BW_PAY_001 | B30: S10 | C30: Payment | D30: Verify payment options display | E30: On checkout | F30: Step 01 | G30: Look at the payment section | H30: UPI and card options | I30: Online payment (payment gateway, UPI, cards) is greyed out with 'Opening soon'; Cash on Delivery (Additional ₹30 fee) is selected | K30: High | L30: Pass | M30: Functional | N30: Both
F31: Step 02 | G31: Try clicking the online payment option
A32: TC_BW_ORD_001 | B32: S11 | C32: Order | D32: Place a Cash on Delivery order end to end | E32: Real name, mobile and email ready; PIN 202002 | F32: Step 01 | G32: Add a product | H32: Beetroot x1, PIN 202002. Expect subtotal 399, shipping 49, COD fee 30, total 478; button reads PLACE CASH ON DELIVERY ORDER (₹478) | I32: Confirmation page with an order reference (BHU-...); bag empties; totals match checkout (₹478) | K32: High | L32: Pass | M32: End-to-End | N32: Both
F33: Step 02 | G33: Fill checkout with real details
F34: Step 03 | G34: Select Cash on Delivery
F35: Step 04 | G35: Place the order
F36: Step 05 | G36: Note the BHU reference
A37: TC_BW_DISC_001 | B37: S12 | C37: Discount codes | D37: Verify discount codes apply, fail and remove (after A10) | E37: Codes created in A10; use the Discount code box and Apply button in the checkout order summary | F37: Step 01 | G37: Apply a valid code | H37: Codes from A10 | I37: Discount line appears and applies to the products total only (shipping and the COD fee are never discounted); wrong code says 'not valid'; minimum-order message shows; Remove clears it | K37: High | L37: Pass | M37: Functional | N37: Both
F38: Step 02 | G38: Apply a wrong code
F39: Step 03 | G39: Apply the minimum-order code on a small bag
F40: Step 04 | G40: Click Remove
...

Sheet Regression
A1: Regression Id | B1: Linked Test Case Id | C1: Scenario | D1: Test Case | E1: Client Check | F1: Run 1 Status | G1: Run 2 Status | H1: Remarks
A2: RG_001 | B2: TC_BW_HOME_001 | C2: Home page | D2: Verify home page, product carousel and links | E2: S1 | F2: Pass
A3: RG_002 | B3: TC_BW_COLL_001 | C3: Collection page | D3: Verify category tabs and search | E3: S2 | F3: Blocked
A4: RG_003 | B4: TC_BW_PDP_001 | C4: Product page | D4: Verify product page photos, price, reviews and WhatsApp | E4: S3 | F4: Pass
A5: RG_004 | B5: TC_BW_BAG_001 | C5: Bag | D5: Verify bag add, quantity change, remove and free-delivery note | E5: S4 | F5: Pass
A6: RG_005 | B6: TC_BW_BAG_002 | C6: Bag | D6: Verify quantity limit of 10 | E6: S5 | F6: Pass
A7: RG_006 | B7: TC_BW_CHK_001 | C7: Checkout form | D7: Verify empty and invalid checkout fields | E7: S6 | F7: Pass
A8: RG_007 | B8: TC_BW_PIN_001 | C8: PIN code | D8: Verify deliverable PIN 202002 | E8: S7 | F8: Pass
A9: RG_008 | B9: TC_BW_PIN_002 | C9: PIN code | D9: Verify non-served PIN 744101 blocks order | E9: S8 | F9: Pass
A10: RG_009 | B10: TC_BW_PIN_003 | C10: PIN code | D10: Verify non-real PIN 999999 blocks order | E10: S9 | F10: Pass
A11: RG_010 | B11: TC_BW_PAY_001 | C11: Payment | D11: Verify payment options display | E11: S10 | F11: Pass
A12: RG_011 | B12: TC_BW_ORD_001 | C12: Order | D12: Place a Cash on Delivery order end to end | E12: S11 | F12: Pass
A13: RG_012 | B13: TC_BW_DISC_001 | C13: Discount codes | D13: Verify discount codes apply, fail and remove (after A10) | E13: S12 | F13: Pass
... A31: RG_030 | B31: TC_BW_HOME_002 | C31: Home page | D31: Verify hero, trust strip, section CTAs and the video | E31: Added | F31: Pass
A32: RG_031 | B32: TC_BW_NAV_001 | C32: Navigation | D32: Verify header menu, logo and sticky behaviour | E32: Added | F32: Pass | H32: Logo wasn't visible in Desktop mode on mobile in some widths in Run 1
A33: RG_032 | B33: TC_BW_NAV_002 | C33: Navigation | D33: Verify mobile hamburger menu | E33: Added | F33: Pass
A34: RG_033 | B34: TC_BW_PDP_002 | C34: Product pages | D34: Verify all 5 products: photos, description, usage, ingredients | E34: Added | F34: Pass
A35: RG_034 | B35: TC_BW_BAG_003 | C35: Bag | D35: Verify bag open and close methods across pages | E35: Added | F35: Pass
A36: RG_035 | B36: TC_BW_BAG_004 | C36: Bag | D36: Verify free-shipping threshold boundaries and progress bar | E36: Added | F36: Pass
A37: RG_036 | B37: TC_BW_CHK_002 | C37: Checkout form | D37: Verify field validation boundaries | E37: Added | F37: Fail
A38: RG_037 | B38: TC_BW_CHK_003 | C38: Checkout form | D38: Verify PIN, city and state consistency | E38: Added | F38: Fail
A39: RG_038 | B39: TC_BW_CHK_004 | C39: Checkout form | D39: Verify double submit, refresh and Back after placing an order | E39: Added | F39: Pass
A40: RG_039 | B40: TC_BW_CHK_005 | C40: Checkout form | D40: Verify order summary and totals on checkout | E40: Added | F40: Pass
A41: RG_040 | B41: TC_BW_CHK_009 | C41: Checkout form | D41: Verify script and SQL input in all fields | E41: Added | F41: Fail
A42: RG_041 | B42: TC_BW_ORD_002 | C42: Order data | D42: Verify one order shows identical data everywhere | E42: Added | F42: Pass
A43: RG_042 | B43: TC_BW_ORD_003 | C43: Order data | D43: Verify stock reduces after an order | E43: Added | F43: Pass
A44: RG_043 | B44: TC_BW_ORD_004 | C44: Order data | D44: Verify ordering more than available stock | E44: Added | F44: Pass
... A62: RG_061 | B62: TC_BW_ADM_026 | C62: Admin discounts | D62: Verify the Create a discount code form validation | E62: Added | F62: Pass
